Workbook
Name t_7092566280593B3BB2C1334FFD87BB75: 'Dropdown Lists'!$C$1:$N$1
Name t_EBE942180826316599849DBDC67BC840: 'Dropdown Lists'!$C$2:$D$2
Name t_B57E8C7A770F35A0BB7753EC0D5DEE56: 'Dropdown Lists'!$C$3:$D$3
Name t_14F2526269293CCF896C9AED8757E81A: 'Dropdown Lists'!$C$4:$G$4
Name t_12506A60C0C93D84978C908BCC35B3F8: 'Dropdown Lists'!$C$5:$H$5
Name t_8A82F0D250A131CB9678F7CD269E83CC: 'Dropdown Lists'!$C$6:$F$6
Name t_CAFFECC57A233C6B8496E27E94BD00CB: 'Dropdown Lists'!$C$7:$P$7
Name t_D6AB99606DBC3456B889DB0B1F4983B5: 'Dropdown Lists'!$C$8:$V$8
Name t_1E1124B7FC7B3954A750E25A69DB0658: 'Dropdown Lists'!$C$9:$L$9
Name t_051693175F4C3966A32680C3E926669D: 'Dropdown Lists'!$C$10:$F$10
Name t_8D7DCDFB1275340BB941677042807F6D: 'Dropdown Lists'!$C$11:$K$11
Name t_918E40D3EBF332149A0D44DF1196300A: 'Dropdown Lists'!$C$12:$K$12
Name t_B828B691B56D3478B51C1F1C2D71B611: 'Dropdown Lists'!$C$13:$S$13
Name t_967ABFFF1F2A3DF9AD8906E53C9D7D59: 'Dropdown Lists'!$C$14:$G$14
Name t_D959B5776CF4385C84E15E547C8B411C: 'Dropdown Lists'!$C$15:$H$15
Name t_96546FBB0668356C839991263B8C6D21: 'Dropdown Lists'!$C$16:$E$16
Name t_DA27226285E53EEF9D162B1EF4365EE2: 'Dropdown Lists'!$C$17:$C$17
Name t_A27F3AA7885C3505852C3B301309B57B: 'Dropdown Lists'!$C$18:$C$18
Name t_3773E4160E40388BA98ED300101B52CD: 'Dropdown Lists'!$C$19:$BY$19
Name t_8814DB9E78153D73A2DE4EFFFCEF1256: 'Dropdown Lists'!$C$20:$BU$20
Name t_D166DE0F832B3D4689BF54F4F9DD5454: 'Dropdown Lists'!$C$21:$BY$21
Name t_A20C14220EF237158FD9CCA8C686F5B6: 'Dropdown Lists'!$C$22:$BY$22
Name t_F98DCB3AE762307DA38D7F30833DF73F: 'Dropdown Lists'!$C$23:$H$23
Name t_C01086A5CDC33871996916645423B4C8: 'Dropdown Lists'!$C$24:$H$24
Name t_1DEB50D24B7633DEB568D46CD0DEE18A: 'Dropdown Lists'!$C$25:$H$25
Name t_10B93B27AE6432F7A309E668D2CC9EDD: 'Dropdown Lists'!$C$26:$H$26
Name t_7BF920BAC1E832CBA736C384387E7A64: 'Dropdown Lists'!$C$27:$D$27
Name t_1A4E538CD7F63317BF625E62EEEBBC3D: 'Dropdown Lists'!$C$28:$D$28
Name t_D8E40E3C11163CDE8776515BCDB9008B: 'Dropdown Lists'!$C$29:$D$29
Name t_E18D138B932938D2B244867CB5CA5F8D: 'Dropdown Lists'!$C$30:$D$30
Name t_2641CB45323E330DA4A86DBF28925232: 'Dropdown Lists'!$C$31:$D$31
Name t_5902DC47A34934A6B275A7ABB0F18706: 'Dropdown Lists'!$C$32:$D$32
Name t_A8996EFB19463551AD2FD78E6CFFFA06: 'Dropdown Lists'!$C$33:$D$33
Name t_E412CE876AE93AD5AC0D5C1480E444C3: 'Dropdown Lists'!$C$34:$D$34
Name t_8ED06C1BC7523579B7FCB86101DC9F37: 'Dropdown Lists'!$C$35:$D$35
Name t_261CDA0339713BDD94255721F6AC1E98: 'Dropdown Lists'!$C$36:$D$36
Name t_5A6FEE3097733D8EBA56B406A1BFEBF3: 'Dropdown Lists'!$C$37:$D$37
Name t_8CB41F7CB92D3DE09250B594F82216BC: 'Dropdown Lists'!$C$38:$D$38
Name t_AF77F406BC7B38739E6D8F1879B1781C: 'Dropdown Lists'!$C$39:$D$39
Name t_EB77710FD03D3CB2B57FFC7E3A2B0A38: 'Dropdown Lists'!$C$40:$D$40
Name t_BFF2A9A99B043547BCF1A7250E072E9C: 'Dropdown Lists'!$C$41:$D$41
Name t_76884B4ABFE53376A65A72677CABCE3D: 'Dropdown Lists'!$C$42:$D$42
Name t_BBF50BEADA7C326398209A43F6AD8F09: 'Dropdown Lists'!$C$43:$D$43
Name t_B49ECF871E0F3408BE31D0994F96041B: 'Dropdown Lists'!$C$44:$D$44
Name t_93A7B5EFF15F3A8F92108126979F2A18: 'Dropdown Lists'!$C$45:$D$45
Name t_2513B871335C3DAB8A733A8C3D70AE77: 'Dropdown Lists'!$C$46:$D$46
Name t_F672583C87EE37CFB0B56C16306BA3CB: 'Dropdown Lists'!$C$47:$D$47
Name t_C8FE43FD1F7F35CAB2C15938EDAD956E: 'Dropdown Lists'!$C$48:$D$48
Name t_A0E4AD6831313900AD961B58EF1C1A77: 'Dropdown Lists'!$C$49:$D$49
Name t_0B2F388CB16F3B18B7491E916140F8B3: 'Dropdown Lists'!$C$50:$D$50
Name t_6433030A9FF83D298602F400E71A99A4: 'Dropdown Lists'!$C$51:$D$51
Name t_438EBE297B01396A97D96656A124EC12: 'Dropdown Lists'!$C$52:$D$52
Name t_76FB370A4ADA3369938705E3B396C3DB: 'Dropdown Lists'!$C$53:$D$53
Name t_F3F0BCE81CAE3DA08E421109EEFE4D3E: 'Dropdown Lists'!$C$54:$D$54
Name t_0B6A9C9F1908395D95B606E715119DED: 'Dropdown Lists'!$C$55:$BS$55
Name t_0815AE15C0663BAE95DDDC17B942AA0E: 'Dropdown Lists'!$C$56:$BS$56
Name t_2176EB6E9ECC38E99443FCEA3B6EAFFB: 'Dropdown Lists'!$C$57:$BS$57
Name t_56720A2F7E653636BA1E4305A9628763: 'Dropdown Lists'!$C$58:$BS$58
Name t_D097CE9D29693045AE3A663CF490EEC0: 'Dropdown Lists'!$C$59:$BS$59
Name t_77B205B7C3DD3B1BBEF38D3B352A8D84: 'Dropdown Lists'!$C$60:$BS$60

Sheet Anleitung
A1: Anwendungsleitfaden für Vorlagen
A2: Diese Seite drucken
A3: Auf dieser Seite finden Sie die notwendigen Informationen, um Ihre Tabellenvorlage zu erstellen, zu überprüfen und an Temu zu übermitteln. Wir empfehlen Ihnen, diese Seite auszudrucken, damit Sie die Informationen während des gesamten Prozesses leicht nachschlagen können.
A4: Speichern Sie eine Version dieser Datei im Excel-Format auf Ihrer Festplatte. Geben Sie anschließend Ihre Produktinformationen gemäß den folgenden Anweisungen in die Registerkarte „Vorlage“ ein.
A6: Registerkarte „Bilder“
A7: Auf der Registerkarte „Bilder“ können Sie sich mit den Leitlinien von Temu für visuelle Inhalte vertraut machen. Stellen Sie sicher, dass die Bilder, die Sie zu Temu beisteuern, diesen festgelegten Standards entsprechen, um Einheitlichkeit und eine hohe Qualität zu gewährleisten.
A8: Für jedes Produkt muss unbedingt ein Bild bereitgestellt werden. Laden Sie Bilder hoch, indem Sie die Bild-URL angeben.
A10: Registerkarte „Beispiel“
A11: Auf der Registerkarte „Beispiel“ finden Sie ein Beispiel für die Eingabe von Produktdaten. Dies dient nur zu Ihrer Orientierung. Denken Sie daran: Um zu verhindern, dass falsche Produktinformationen in Ihre Bestandsdatei aufgenommen werden, sollten Sie ihre eigenen Produkte nicht direkt im Beispielblatt bearbeiten.
A13: Template Tab
A14: 1. Empfohlene Software: Aufgrund von Überlegungen zur Dateikompatibilität wird Office Excel empfohlen, um die Vorlagendatei zu nutzen und zu bearbeiten. 2. Integrität der Vorlage: Ändern oder löschen Sie in der Vorlagendatei keine Arbeitsblattnamen, Spaltenüberschriften oder deren Reihenfolge. Wählen Sie für Zellen mit Dropdown-Aufzählungen Werte aus der Dropdown-Liste aus, und geben Sie sie ein. 3. Maßeinheiten: Die Einheiten in der Vorlagendatei beziehen sich auf die Veröffentlichungswebsite a. Der Verkaufsort USA verwendet das angloamerikanische (imperiale) System: Die Längeneinheit ist Zoll, die Gewichtseinheit ist Pfund und die Währungseinheit ist USD 1. Der Längenbereich liegt zwischen 0,1 Zoll und 999,9 Zoll mit maximal 1 Dezimalstelle und wird aufgerundet. 2. Der Gewichtsbereich liegt zwischen 0,1 lb und 9999,9 lb mit maximal 1 Dezimalstelle und wird aufgerundet. 3. Der Preisbereich liegt zwischen 0,01 $ und 99999999,99 $ mit maximal 2 Dezimalstellen und wird aufgerundet. a. Der Verkaufsort Mexiko verwendet das metrische System: Die Längeneinheit ist Zentimeter, die Gewichtseinheit ist Gramm und die Währungseinheit ist MXN Der Längenbereich liegt zwischen 0,1 cm und 9999999,9 cm mit maximal 1 Dezimalstelle und wird aufgerundet. ii. Der Gewichtsbereich liegt zwischen 0,1 g und 9999,9 g mit maximal 1 Dezimalstelle und wird aufgerundet. iii. Der Preisbereich liegt zwischen 0,01 MX$ und 99999999,99 MX$ mit maximal 2 Dezimalstellen und wird aufgerundet. c. Die deutschen, italienischen, französischen und spanischen Verkaufsorte verwenden alle das metrische System: Die Längeneinheit ist Zentimeter, die Gewichtseinheit ist Gramm und die Währungseinheit ist EUR 1. Der Längenbereich liegt zwischen 0,1 cm und 9999999,9 cm mit maximal 1 Dezimalstelle und wird aufgerundet. 2. Der Gewichtsbereich liegt zwischen 0,1 g und 9999,9 g mit maximal 1 Dezimalstelle und wird aufgerundet. 3. Der Preisbereich liegt zwischen 0,01 € und 99999999,99 € mit maximal 2 Dezimalstellen und wird aufgerundet. d. Der Verkaufsort Vereinigtes Königreich verwendet das metrische System: Die Längeneinheit ist Zentimeter, die Gewichtseinheit ist Gramm und die Währungseinheit ist GBP 1. Der Längenbereich liegt zwischen 0,1 cm und 9999999,9 cm mit maximal 1 Dezimalstelle und wird aufgerundet. 2. Der Gewichtsbereich liegt zwischen 0,1 g und 9999,9 g mit maximal 1 Dezimalstelle und wird aufgerundet. 3. Der Preisbereich liegt zwischen 0,01 £ und 99999999,99 £ mit maximal 2 Dezimalstellen und wird aufgerundet. 4. Qualifikationen und Fotos: Excel unterstützt derzeit nicht das Hochladen von Qualifizierungsdokumenten oder Fotos. Wenn für Produkte diese Materialien erforderlich sind, stellen Sie diese nach der Einreichung der Produkte auf der Seite „Produkt-Compliance“ bereit. 5. Pflichtfelder: Die Excel-Datei enthält integrierte Formeln. Nach der Auswahl der Kategorie führt Excel Folgendes aus: a. Kennzeichnet Pflichtfelder mit roten Umrandungen. b. Verwendet graue Felder zur Kennzeichnung von Feldern, die leer bleiben sollen. c. Verwendet weiße Felder zur Kennzeichnung von optionalen Feldern. d. Bitte stellen Sie sicher, dass in jeder Zeile alle erforderlichen Informationen korrekt und vollständig ausgefüllt sind. Stellen Sie sicher, dass alle Pflichtfelder korrekt ausgefüllt sind. e. Optionale Felder müssen zwar nicht ausgefüllt werden, doch wenn Sie so viele Informationen wie möglich angeben, kann dies beim Verkauf von Produkten hilfreich sein. 6. Mengenbegrenzung: In jeder Datei sind bis zu 200 Zeilen Inhalt zulässig, andernfalls können Produkte nicht zur Datei hinzugefügt werden. 7. Doppelte Spalten: Die Excel-Datei ist standardmäßig zugeklappt. Sie können oben in der Excel-Datei auf 1 und 2 klicken. 8. Verwenden Sie die neueste Vorlage, da Temu gültige Werte, Datenvalidierungsregeln, einen erläuternden Text oder Anforderungen in der Vorlage von Zeit zu Zeit aktualisiert.
A17: Tabelle einreichen
... A23: Von Zeit zu Zeit aktualisiert Temu Dinge wie Aktivitätsanforderungen, Datenvalidierungsregeln und erläuternden Text. Bitte verwende die zuletzt generierte Vorlage, wenn eine neue Vorlage angezeigt wird.

Sheet Bilder
A1: Bildstandards
A2: Für jedes Produkt auf Temu muss mindestens ein Produktbild bereitgestellt werden. Wählen Sie klare, unkomplizierte und leicht verständliche Bilder. Sie müssen das Produkt genau darstellen, informativ sein und ansprechend präsentiert werden. Zeigen Sie nur das Produkt, das zum Verkauf angeboten wird. Stellen Sie nach Möglichkeit mehrere Bilder zur Verfügung, die jeweils verschiedene Blickwinkel und Details des Produkts zeigen. Dies ist Ihre Gelegenheit, Ihrem Kunden Ihr Produkt zu präsentieren, also ist Qualität wichtig.
A3: Wir behalten uns das Recht vor, Bilder abzulehnen, die nicht unseren Bildstandards entsprechen.
A4: Es liegt in Ihrer Verantwortung, sicherzustellen, dass Sie alle erforderlichen Rechte an den von Ihnen eingereichten Bildern besitzen.
A6: SKU-Bilder
A7: Die SKU-Bilder werden oben auf der Produktseite angezeigt. Verschiedene SKU-Bilder bilden ein Karussell des Produkts.
A8: Bei Bekleidungsprodukten sollten die hochgeladenen Bilder eine maximale Größe von 3 MB, ein Seitenverhältnis von 3:4, eine Breite von ≥ 1340 px und eine Höhe von ≥ 1785 px haben. Die SKUs mit derselben Farbe teilen sich einen Satz von Karussellbildern.
A9: Bei anderen Produkten als Bekleidungsprodukten sollten die hochgeladenen Bilder eine maximale Größe von 3 MB, ein Seitenverhältnis von 1:1 und eine Breite und Höhe von ≥ 800 px aufweisen.
A10: Du kannst bis zu zehn Bilder hochladen, wobei jede Zelle eine Bild-URL enthält.
A12: Produktvideo
A13: Das Produktvideo wird oben auf der Produktseite angezeigt.
A14: Das hochgeladene Video sollte eine maximale Größe von 100 MB, eine Länge von maximal 180 Sekunden und eine Mindestauflösung von 720 p haben.
... A23: Laden Sie das Video mit einer maximalen Größe von 300 MB, einer Länge von maximal 180 Sekunden, einem Seitenverhältnis von 1:1, 4:3 oder 16:9 und einer Mindestauflösung von 720p hoch.

Sheet Beispiel
A1: 1. Bitte schauen Sie sich nicht nur den Inhalt der Registerkarte „Beispiel“ an, sondern auch die Registerkarte „Anleitungen“ in diesem Dokument.
A2: 2. Beachten Sie, dass die angeführten Beispiele lediglich der Veranschaulichung dienen. Die in Ihrer angepassten Vorlage angezeigten Spalten variieren je nach der ausgewählten Kategorie. Verwenden Sie die Registerkarte „Vorlage“, um die Tabellenvorlage zu erstellen.
A3: 3. Einige der optionalen Spalten sind eingeklappt, um eine bessere Darstellung zu ermöglichen. Lassen Sie diese ausgeblendeten Bereiche anzeigen, indem Sie in der entsprechenden Spalte oder im entsprechenden Abschnitt auf die Schaltfläche „+“ klicken
A4: 4. Fehler beim Senden eines Produkteintrags können durch Anzeigen der Verarbeitungsergebnisse oder durch Kontaktaufnahme mit dem Verkäufersupport behoben werden.
A5: Einige Felder sind Pflichtfelder. Andere sind optional. | B5: Product Identity | H5: Product Description | BN5: Product Detail | GT5: Sale Property (At Least One, At Most Two) | HL5: Size Chart | IE5: Variations | IY5: Offer | JC5: Qualifications
B6: Category | C6: Product Name | D6: Contribution Goods | E6: Contribution SKU | F6: Brand | G6: Trademark | H6: Product Description | I6: Bullet Point | J6: Bullet Point | K6: Bullet Point | L6: Bullet Point | M6: Bullet Point | N6: Bullet Point | O6: Detail Images URL | P6: Detail Images URL | Q6: Detail Images URL | R6: Detail Images URL | S6: Detail Images URL | T6: Detail Images URL | U6: Detail Images URL | V6: Detail Images URL | W6: Detail Images URL | X6: Detail Images URL | Y6: Detail Images URL | Z6: Detail Images URL | AA6: Detail Images URL | AB6: Detail Images URL | AC6: Detail Images URL | AD6: Detail Images URL | AE6: Detail Images URL | AF6: Detail Images URL | AG6: Detail Images URL | AH6: Detail Images URL | AI6: Detail Images URL | AJ6: Detail Images URL | AK6: Detail Images URL | AL6: Detail Images URL | AM6: Detail Images URL | AN6: Detail Images URL | AO6: Detail Images URL | AP6: Detail Images URL | AQ6: Detail Images URL | AR6: Detail Images URL | AS6: Detail Images URL | AT6: Detail Images URL | AU6: Detail Images URL | AV6: Detail Images URL | AW6: Detail Images URL | AX6: Detail Images URL | AY6: Detail Images URL | AZ6: Detail Images URL | BA6: Detail Images URL | BB6: Detail Images URL | BC6: Detail Images URL | BD6: Detail Images URL | BE6: Detail Images URL | BF6: Detail Images URL | BG6: Detail Images URL | BH6: Detail Images URL | BI6: Detail Images URL | BJ6: Detail Images URL | BK6: Detail Images URL | BL6: Detail Images URL | BM6: Detail Video URL | BN6: 4115 - Shelf Life - value | BO6: 4115 - Shelf Life - unit | BP6: 4118 - Speciality | BQ6: 4118 - Speciality | BR6: 4118 - Speciality | BS6: 4119 - Item Weight - value | BT6: 4119 - Item Weight - unit | BU6: 4120 - Package Weight - value | BV6: 4120 - Package Weight - unit | BW6: 4121 - Allergen Information | BX6: 4121 - Allergen Information | BY6: 4121 - Allergen Information | BZ6: 4121 - Allergen Information | CA6: 4121 - Allergen Information | CB6: 4121 - Allergen Information | CC6: 4121 - Allergen Information | CD6: 4121 - Allergen Information | CE6: 4121 - Allergen Information | CF6: 4121 - Allergen Information | CG6: 195 - Diet Type | CH6: 195 - Diet Type | CI6: 195 - Diet Type | CJ6: 6160 - Brand Name | CK6: 6210 - USDA certified | CL6: 4110 - Production Date | CM6: 6440 - best before | CN6: 361 - Package Quantity | CO6: 12 - Material | CP6: 12 - Material | CQ6: 12 - Material | CR6: 12 - Material | CS6: 12 - Material | CT6: 4134 - Publisher | CU6: 4130 - Country/Region Of Origin | CV6: 4137 - Author | CW6: 1120 - Set or not | CX6: 4133 - Binding Type | CY6: 4123 - Languages | CZ6: 4123 - Languages | DA6: 4123 - Languages | DB6: 4142 - Year Of Publication | DC6: 4124 - Number Of Pages (pages) - value | DD6: 4124 - Number Of Pages (pages) - unit | DE6: 4131 - Number Of Words (10,000 Words) | DF6: 4127 - Product Weight (g) - value | DG6: 4127 - Product Weight (g) - unit | DH6: 4128 - Maximum Reading Age (years) - value | DI6: 4128 - Maximum Reading Age (years) - unit | DJ6: 4129 - Minimum Reading Age (years) - value | DK6: 4129 - Minimum Reading Age (years) - unit | DL6: 121 - Material | DM6: 121 - Material | DN6: 121 - Material | DO6: 121 - Material | DP6: 121 - Material | DQ6: 132 - Finish Type | DR6: 210 - Furniture Finish | DS6: 19 - Style | DT6: 1561 - Power Supply | DU6: 1132 - Operating Voltage | DV6: 1485 - Plug Type | DW6: 1485 - Plug Type | DX6: 1485 - Plug Type | DY6: 1571 - Acceptable Voltage Range | DZ6: 4102 - Contain Wooden Materials | EA6: 4097 - Tree Species | EB6: 4097 - Tree Species | EC6: 4098 - Wood Formation Type | ED6: 4098 - Wood Formation Type | EE6: 4098 - Wood Formation Type | EF6: 4099 - Fiberboard Density | EG6: 6171 - Wether Independent | EH6: 6172 - Closed Storage Capacity | EI6: 6173 - Height After Assembly | EJ6: 6174 - Physical Weight | EK6: 2153 - Battery Properties | EL6: 2147 - Rechargeable Battery | EM6: 2154 - Solar Battery Type | EN6: 3740 - Non-rechargeable Battery | EO6: 2028 - Battery Capacity (mAh) - value | EP6: 2028 - Battery Capacity (mAh) - unit | EQ6: 63 - Color | ER6: 15 - Composition:Nylon | ES6: 15 - Composition:Polyester | ET6: 15 - Composition:Polyamide | EU6: 15 - Composition:Elastane | EV6: 15 - Composition:Spandex | EW6: 15 - Composition:Acrylic | EX6: 15 - Composition:Cotton | EY6: 15 - Composition:Silk | EZ6: 15 - Composition:Linen | FA6: 15 - Composition:Modal | FB6: 15 - Composition:Viscose | FC6: 15 - Composition:Rayon | FD6: 15 - Composition:Carbon | FE6: 15 - Composition:Metal | FF6: 15 - Composition:Wool | FG6: 15 - Composition:Cashmere | FH6: 15 - Composition:Mohair | FI6: 15 - Composition:Rabbit Hair | FJ6: 15 - Composition:Bovine Leather | FK6: 15 - Composition:Sheep Leather | FL6: 15 - Composition:Pig Leather | FM6: 15 - Composition:Polyurethane | FN6: 15 - Composition:Polyvinyl Chloride | FO6: 15 - Composition:Cupro | FP6: 15 - Composition:Lyocell | FQ6: 15 - Composition:Acetate | FR6: 15 - Composition:Down | FS6: 15 - Composition:Feather | FT6: 15 - Composition:Duck Down | FU6: 15 - Composition:Alpaca | FV6: 15 - Composition:Metallized Fibres | FW6: 15 - Composition:Polypropylene fibers | FX6: 15 - Composition:Other Fibers | FY6: 28 - Length | FZ6: 74 - Belt | GA6: 29 - Sleeve Length | GB6: 27 - Sleeve Type | GC6: 94 - Chest Pad | GD6: 83 - Details | GE6: 26 - Pattern | GF6: 24 - Sheer | GG6: 22 - Fabric | GH6: 86 - Placket Type | GI6: 78 - Lining | GJ6: 113 - Contour | GK6: 76 - Season | GL6: 20 - Operation Instruction | GM6: 114 - Fit Type | GN6: 1352 - Fabric Elasticity | GO6: 1919 - Printing Type | GP6: 2103 - Style source | GQ6: 1192 - Weaving Method | GR6: 21 - Collar Style | GS6: 6227 - Collection | GT6: Variation Theme | GU6: Size Family | GV6: Sub-Size Family | GW6: Size | GX6: Color | GY6: Color | GZ6: Size | HA6: Style | HB6: Material | HC6: Flavors | HD6: Applicable People | HE6: Capacity | HF6: Composition | HG6: Weight | HH6: Items | HI6: Quantity | HJ6: Model | HK6: Hair Length | HL6: Unit | HM6: US Size | HN6: Tops - Product - Shoulder width | HO6: Tops - Product - Bust size | HP6: Tops - Product - Clothes length | HQ6: Tops - Product - Sleeve length | HR6: Tops - Product - Waist size | HS6: Tops - Product - Underbust | HT6: Tops - Product - Neck | HU6: Tops - Product - Hem | HV6: Tops - Product - Cuffs | HW6: Tops - Body - Bust - min | HX6: Tops - Body - Bust - max | HY6: Tops - Body - Waist - min | HZ6: Tops - Body - Waist - max | IA6: Tops - Body - Hips - min | IB6: Tops - Body - Hips - max | IC6: Tops - Body - Height - min | ID6: Tops - Body - Height - max | IE6: SKU Images URL | IF6: SKU Images URL | IG6: SKU Images URL | IH6: SKU Images URL | II6: SKU Images URL | IJ6: SKU Images URL | IK6: SKU Images URL | IL6: SKU Images URL | IM6: SKU Images URL | IN6: SKU Images URL | IO6: Quantity | IP6: Base Price - EUP | IQ6: List Price - EUP | IR6: Not available for List price | IS6: Weight - g | IT6: Length - cm | IU6: Width - cm | IV6: Height - cm | IW6: External Product ID Type | IX6: External Product ID | IY6: Handling Time | IZ6: Shipping Template | JA6: Import Designation | JB6: Item Tax Code | JC6: Product Guide
A7: Beispiel 1: Dies ist ein Beispiel für die Bereitstellung eines neuen Angebots. Dieses Beispiel hat keine Variation und wird als einzelne Detailseite aufgeführt. | B7: 29069 | C7: Example Women T-shirt, 156 Black T-shirt | D7: EXAMPLE-156-US-Black-one-size | E7: EXAMPLE-156-US-Black-one-size | H7: Unleash your personal style with our classic fit tee. Crafted from 100% cotton, it offers unmatched comfort and durability. The tee features a unique, eye-catching graphic that embodies modern chic. Perfect for casual outings or layering under a jacket, this T-shirt is versatile for any occasion. With a breathable fabric that holds its shape, it's a wardrobe staple you'll reach for time and again. Make a statement and stay cozy in a shirt designed to express who you are. (Character count: 493) | I7: 100% premium cotton for ultimate comfort. | J7: Timeless design meets modern style. | K7: Durable fabric, perfect for daily wear | L7: Machine washable and easy to care for. | M7: Versatile fit for every body type. | O7: http://www.companyname.com/images/1250.main.jpg | P7: http://www.companyname.com/images/1250.main.jpg | Q7: http://www.companyname.com/images/1250.main.jpg | R7: http://www.companyname.com/images/1250.main.jpg | CO7: Recycle Polyester | DS7: Y2K | ER7: 32 | ES7: 28 | ET7: 40 | FY7: Short Length | FZ7: Yes | GA7: Long Sleeve | GB7: Raglan sleeve | GC7: No Padding | GD7: Fake Pockets | GE7: Mushroom | GF7: No | GG7: Non-Stretch | GH7: Half Placket | GI7: Cashmere | GJ7: H | GK7: Fall | GL7: Do not wash | GM7: Regular | GN7: No Elasticity | GO7: Positioning Printing | GP7: Buyer provides | GQ7: Woven | GR7: Off the Shoulder | GS7: Middle East | GT7: Size × Color | GU7: US/EU size | GV7: One Size | GW7: one-size | GX7: Black | HL7: cm | HM7: one-size | HO7: 36 | HP7: 28 | HW7: 33.9 | HX7: 35.5 | HY7: 26 | HZ7: 27.6 | IA7: 35.9 | IB7: 37.4 | IE7: http://www.companyname.com/images/1250.main.jpg | IF7: http://www.companyname.com/images/1250.main.jpg | IG7: http://www.companyname.com/images/1250.main.jpg | IO7: 5 | IP7: 2.99 | IQ7: 5.99 | IS7: 9.2 | IT7: 2 | IU7: 3 | IV7: 4 | IY7: 1 Day | IZ7: test1 | JA7: Imported | JB7: GEN STANDARD
B8: 12408 | C8: Example reclaimed Cabinet Solid Wood with 4 Drawers | D8: EXAMPLE-576-Brown | E8: EXAMPLE-576-Brown | DL8: Wood | DQ8: Painted | DR8: Cedar | DS8: Vintage | DT8: Plug Powered | DU8: 110V (included)-240V (included) | DV8: US Plug | DZ8: Yes | EA8: Hardwood | EC8: Block Board (large Core Board) | EG8: Yes | EH8: <3.2 Cubic Feet | EI8: <27 Inches | EJ8: <30 Lbs | EK8: Without Battery | EQ8: Red | GT8: Color × Style | GY8: Red | HA8: Vintage | IE8: http://www.companyname.com/images/1250.main.jpg | IF8: http://www.companyname.com/images/1250.main.jpg | IG8: http://www.companyname.com/images/1250.main.jpg | IO8: 0 | IP8: 2.99 | IQ8: 5.99 | IS8: 9.2 | IT8: 2 | IU8: 3 | IV8: 4 | IY8: 1 Day | IZ8: test1 | JA8: Imported | JB8: GEN STANDARD | JC8: http://www.companyname.com/images/productguide.pdf
B9: 44936 | C9: Example book for US with isbn | D9: EXAMPLEISBN9787040205190 | E9: EXAMPLEISBN9787040205190 | CT9: Example publisher | CU9: USA | CV9: Example author | CW9: No | CX9: Paperback | CY9: English | DB9: 44604 | DC9: 300 | DD9: Page | DE9: 1000 | DF9: 200 | DG9: g | DH9: 99 | DI9: years old | DJ9: 1 | DK9: years old | GT9: Items | HH9: Example book for US with isbn | IE9: http://www.companyname.com/images/1250.main.jpg | IF9: http://www.companyname.com/images/1250.main.jpg | IG9: http://www.companyname.com/images/1250.main.jpg | IO9: 20 | IP9: 7.82 | IQ9: 10.23 | IS9: 9.2 | IT9: 2 | IU9: 3 | IV9: 4 | IW9: ISBN | IX9: 920000021 | IY9: 1 Day | IZ9: test1 | JA9: Imported | JB9: BOOKS GEN
B10: 42550 | C10: Example food Potato Chips Pack of 6 - 80g per bag | D10: EXAMPLE-Pack6 - 80g | E10: EXAMPLE-Pack6 - 80g | BN10: 30 | BO10: Day | BP10: Wild-Caught | BQ10: Certified-Humane-Raised-And-Handled | BS10: 90 | BT10: g | BU10: 106 | BV10: g | BW10: Contains cow's milk | BX10: Contains Peanuts | CG10: Plant Based | CJ10: Example brand name | CK10: less than 70% organic ingredients | CL10: 45550 | CM10: 45641 | GT10: Weight | HG10: 90g | IE10: http://www.companyname.com/images/1250.main.jpg | IF10: http://www.companyname.com/images/1250.main.jpg | IG10: http://www.companyname.com/images/1250.main.jpg | IO10: 20 | IP10: 5.39 | IR10: N/A | IS10: 9.2 | IT10: 2 | IU10: 3 | IV10: 4 | IY10: 1 Day | IZ10: test1 | JA10: Imported | JB10: FOOD GEN
A12: Beispiel 2: Dies ist ein Beispiel für ein Produkt mit 1 Variationsdesign (Größe) mit 3 Variationen. Dabei handelt es sich um 3 „untergeordnete“ SKUs in einer „übergeordneten“ Ware. Hinweis: Stelln Sie bei Informationen auf Produktebene, wie z. B. Produktname, Produktbeschreibung, Produktdetails, Angebot, Qualifikationen, sicher, dass jede Zeile korrekt ausgefüllt ist und die Informationen einheitlich eingegeben werden. | B12: 29069 | C12: Example Women T-shirt, 156 Black T-shirt | D12: EXAMPLE-156-US-Black | E12: EXAMPLE-156-US-Black-S | H12: Unleash your personal style with our classic fit tee. Crafted from 100% cotton, it offers unmatched comfort and durability. The tee features a unique, eye-catching graphic that embodies modern chic. Perfect for casual outings or layering under a jacket, this T-shirt is versatile for any occasion. With a breathable fabric that holds its shape, it's a wardrobe staple you'll reach for time and again. Make a statement and stay cozy in a shirt designed to express who you are. (Character count: 493) | I12: 100% premium cotton for ultimate comfort. | J12: Timeless design meets modern style. | K12: Durable fabric, perfect for daily wear | L12: Machine washable and easy to care for. | M12: Versatile fit for every body type. | O12: http://www.companyname.com/images/1250.main.jpg | P12: http://www.companyname.com/images/1250.main.jpg | Q12: http://www.companyname.com/images/1250.main.jpg | R12: http://www.companyname.com/images/1250.main.jpg | CO12: Recycle Polyester | DS12: Y2K | ER12: 32 | ES12: 28 | ET12: 40 | FY12: Short Length | FZ12: Yes | GA12: Long Sleeve | GB12: Raglan sleeve | GC12: No Padding | GD12: Fake Pockets | GE12: Mushroom | GF12: No | GG12: Non-Stretch | GH12: Half Placket | GI12: Cashmere | GJ12: H | GK12: Fall | GL12: Do not wash | GM12: Regular | GN12: No Elasticity | GO12: Positioning Printing | GP12: Buyer provides | GQ12: Woven | GR12: Off the Shoulder | GS12: Middle East | GT12: Size × Color | GU12: US/EU size | GV12: Alpha | GW12: S | GX12: Black | HL12: cm | HM12: 0 | HO12: 36 | HP12: 28 | HW12: 33.9 | HX12: 35.5 | HY12: 26 | HZ12: 27.6 | IA12: 35.9 | IB12: 37.4 | IE12: http://www.companyname.com/images/1250.main.jpg | IF12: http://www.companyname.com/images/1250.main.jpg | IG12: http://www.companyname.com/images/1250.main.jpg | IO12: 5 | IP12: 2.99 | IQ12: 5.99 | IS12: 9.2 | IT12: 2 | IU12: 3 | IV12: 4 | IY12: 1 Day | IZ12: test1 | JA12: Imported | JB12: GEN STANDARD
B13: 29069 | C13: Example Women T-shirt, 156 Black T-shirt | D13: EXAMPLE-156-US-Black | E13: EXAMPLE-156-US-Black-M | H13: Unleash your personal style with our classic fit tee. Crafted from 100% cotton, it offers unmatched comfort and durability. The tee features a unique, eye-catching graphic that embodies modern chic. Perfect for casual outings or layering under a jacket, this T-shirt is versatile for any occasion. With a breathable fabric that holds its shape, it's a wardrobe staple you'll reach for time and again. Make a statement and stay cozy in a shirt designed to express who you are. (Character count: 493) | I13: 100% premium cotton for ultimate comfort. | J13: Timeless design meets modern style. | K13: Durable fabric, perfect for daily wear | L13: Machine washable and easy to care for. | M13: Versatile fit for every body type. | O13: http://www.companyname.com/images/1250.main.jpg | P13: http://www.companyname.com/images/1250.main.jpg | Q13: http://www.companyname.com/images/1250.main.jpg | R13: http://www.companyname.com/images/1250.main.jpg | CO13: Recycle Polyester | DS13: Y2K | ER13: 32 | ES13: 28 | ET13: 40 | FY13: Short Length | FZ13: Yes | GA13: Long Sleeve | GB13: Raglan sleeve | GC13: No Padding | GD13: Fake Pockets | GE13: Mushroom | GF13: No | GG13: Non-Stretch | GH13: Half Placket | GI13: Cashmere | GJ13: H | GK13: Fall | GL13: Do not wash | GM13: Regular | GN13: No Elasticity | GO13: Positioning Printing | GP13: Buyer provides | GQ13: Woven | GR13: Off the Shoulder | GS13: Middle East | GT13: Size × Color | GU13: US/EU size | GV13: Alpha | GW13: M | GX13: Black | HL13: cm | HM13: 2 | HO13: 40 | HP13: 29 | HW13: 35.5 | HX13: 37 | HY13: 27.6 | HZ13: 29.2 | IA13: 27.4 | IB13: 39 | IE13: http://www.companyname.com/images/1250.main.jpg | IF13: http://www.companyname.com/images/1250.main.jpg | IG13: http://www.companyname.com/images/1250.main.jpg | IO13: 5 | IP13: 2.99 | IQ13: 5.99 | IS13: 9.2 | IT13: 2 | IU13: 3 | IV13: 4 | IY13: 1 Day | IZ13: test1 | JA13: Imported | JB13: GEN STANDARD
B14: 29069 | C14: Example Women T-shirt, 156 Black T-shirt | D14: EXAMPLE-156-US-Black | E14: EXAMPLE-156-US-Black-L | H14: Unleash your personal style with our classic fit tee. Crafted from 100% cotton, it offers unmatched comfort and durability. The tee features a unique, eye-catching graphic that embodies modern chic. Perfect for casual outings or layering under a jacket, this T-shirt is versatile for any occasion. With a breathable fabric that holds its shape, it's a wardrobe staple you'll reach for time and again. Make a statement and stay cozy in a shirt designed to express who you are. (Character count: 493) | I14: 100% premium cotton for ultimate comfort. | J14: Timeless design meets modern style. | K14: Durable fabric, perfect for daily wear | L14: Machine washable and easy to care for. | M14: Versatile fit for every body type. | O14: http://www.companyname.com/images/1250.main.jpg | P14: http://www.companyname.com/images/1250.main.jpg | Q14: http://www.companyname.com/images/1250.main.jpg | R14: http://www.companyname.com/images/1250.main.jpg | CO14: Recycle Polyester | DS14: Y2K | ER14: 32 | ES14: 28 | ET14: 40 | FY14: Short Length | FZ14: Yes | GA14: Long Sleeve | GB14: Raglan sleeve | GC14: No Padding | GD14: Fake Pockets | GE14: Mushroom | GF14: No | GG14: Non-Stretch | GH14: Half Placket | GI14: Cashmere | GJ14: H | GK14: Fall | GL14: Do not wash | GM14: Regular | GN14: No Elasticity | GO14: Positioning Printing | GP14: Buyer provides | GQ14: Woven | GR14: Off the Shoulder | GS14: Middle East | GT14: Size × Color | GU14: US/EU size | GV14: Alpha | GW14: L | GX14: Black | HL14: cm | HM14: 4 | HO14: 44 | HP14: 30 | HW14: 37.4 | HX14: 39.8 | HY14: 29.6 | HZ14: 31.9 | IA14: 39.4 | IB14: 41.8 | IE14: http://www.companyname.com/images/1250.main.jpg | IF14: http://www.companyname.com/images/1250.main.jpg | IG14: http://www.companyname.com/images/1250.main.jpg | IO14: 5 | IP14: 2.99 | IQ14: 5.99 | IS14: 9.2 | IT14: 2 | IU14: 3 | IV14: 4 | IY14: 1 Day | IZ14: test1 | JA14: Imported | JB14: GEN STANDARD
B15: 12408 | C15: Example reclaimed Cabinet Solid Wood with 4 Drawers | D15: EXAMPLE-576 | E15: EXAMPLE-576-Brown | DL15: Wood | DQ15: Painted | DR15: Cedar | DS15: Vintage | DT15: Plug Powered | DU15: 110V (included)-240V (included) | DV15: US Plug | DZ15: Yes | EA15: Hardwood | EC15: Block Board (large Core Board) | EG15: Yes | EH15: <3.2 Cubic Feet | EI15: <27 Inches | EJ15: <30 Lbs | EK15: Without Battery | EQ15: Red | GT15: Color | GY15: Brown | IE15: http://www.companyname.com/images/1250.main.jpg | IF15: http://www.companyname.com/images/1250.main.jpg | IG15: http://www.companyname.com/images/1250.main.jpg | IO15: 5 | IP15: 2.99 | IQ15: 5.99 | IS15: 9.2 | IT15: 2 | IU15: 3 | IV15: 4 | IY15: 1 Day | IZ15: test1 | JA15: Imported | JB15: GEN STANDARD
B16: 12408 | C16: Example reclaimed Cabinet Solid Wood with 4 Drawers | D16: EXAMPLE-576 | E16: EXAMPLE-576-white | DL16: Wood | DQ16: Painted | DR16: Cedar | DS16: Vintage | DT16: Plug Powered | DU16: 110V (included)-240V (included) | DV16: US Plug | DZ16: Yes | EA16: Hardwood | EC16: Block Board (large Core Board) | EG16: Yes | EH16: <3.2 Cubic Feet | EI16: <27 Inches | EJ16: <30 Lbs | EK16: Without Battery | EQ16: Red | GT16: Color | GY16: white | IE16: http://www.companyname.com/images/1250.main.jpg | IF16: http://www.companyname.com/images/1250.main.jpg | IG16: http://www.companyname.com/images/1250.main.jpg | IO16: 5 | IP16: 2.99 | IQ16: 5.99 | IS16: 9.2 | IT16: 2 | IU16: 3 | IV16: 4 | IY16: 1 Day | IZ16: test1 | JA16: Imported | JB16: GEN STANDARD
B17: 12408 | C17: Example reclaimed Cabinet Solid Wood with 4 Drawers | D17: EXAMPLE-576 | E17: EXAMPLE-576-red | DL17: Wood | DQ17: Painted | DR17: Cedar | DS17: Vintage | DT17: Plug Powered | DU17: 110V (included)-240V (included) | DV17: US Plug | DZ17: Yes | EA17: Hardwood | EC17: Block Board (large Core Board) | EG17: Yes | EH17: <3.2 Cubic Feet | EI17: <27 Inches | EJ17: <30 Lbs | EK17: Without Battery | EQ17: Red | GT17: Color | GY17: red | IE17: http://www.companyname.com/images/1250.main.jpg | IF17: http://www.companyname.com/images/1250.main.jpg | IG17: http://www.companyname.com/images/1250.main.jpg | IO17: 5 | IP17: 2.99 | IQ17: 5.99 | IS17: 9.2 | IT17: 2 | IU17: 3 | IV17: 4 | IY17: 1 Day | IZ17: test1 | JA17: Imported | JB17: GEN STANDARD
A19: Beispiel 3: Dies ist ein Beispiel für ein Produkt mit 2 Variationsdesigns (Größe und Farbe) mit 4 Variationen. Dabei handelt es sich um 4 „untergeordnete“ SKUs in einer „übergeordneten“ Ware. Hinweis: Stellen Sie bei Informationen auf Produktebene, wie z. B. Produktname, Produktbeschreibung, Produktdetails, Angebot, Qualifikationen, sicher, dass jede Zeile korrekt ausgefüllt ist und die Informationen einheitlich eingegeben werden. | B19: 29069 | C19: Example Women T-shirt, 156 Black T-shirt | D19: EXAMPLE-156-US | E19: EXAMPLE-156-US-Black-S | H19: Unleash your personal style with our classic fit tee. Crafted from 100% cotton, it offers unmatched comfort and durability. The tee features a unique, eye-catching graphic that embodies modern chic. Perfect for casual outings or layering under a jacket, this T-shirt is versatile for any occasion. With a breathable fabric that holds its shape, it's a wardrobe staple you'll reach for time and again. Make a statement and stay cozy in a shirt designed to express who you are. (Character count: 493) | I19: 100% premium cotton for ultimate comfort. | J19: Timeless design meets modern style. | K19: Durable fabric, perfect for daily wear | L19: Machine washable and easy to care for. | M19: Versatile fit for every body type. | O19: http://www.companyname.com/images/1250.main.jpg | P19: http://www.companyname.com/images/1250.main.jpg | Q19: http://www.companyname.com/images/1250.main.jpg | R19: http://www.companyname.com/images/1250.main.jpg | CO19: Recycle Polyester | DS19: Y2K | ER19: 32 | ES19: 28 | ET19: 40 | FY19: Short Length | FZ19: Yes | GA19: Long Sleeve | GB19: Raglan sleeve | GC19: No Padding | GD19: Fake Pockets | GE19: Mushroom | GF19: No | GG19: Non-Stretch | GH19: Half Placket | GI19: Cashmere | GJ19: H | GK19: Fall | GL19: Do not wash | GM19: Regular | GN19: No Elasticity | GO19: Positioning Printing | GP19: Buyer provides | GQ19: Woven | GR19: Off the Shoulder | GS19: Middle East | GT19: Size × Color | GU19: US/EU size | GV19: Alpha | GW19: S | GX19: Black | HL19: cm | HM19: 0 | HO19: 36 | HP19: 28 | HW19: 33.9 | HX19: 35.5 | HY19: 26 | HZ19: 27.6 | IA19: 35.9 | IB19: 37.4 | IE19: http://www.companyname.com/images/1250.main.jpg | IF19: http://www.companyname.com/images/1250.main.jpg | IG19: http://www.companyname.com/images/1250.main.jpg | IO19: 5 | IP19: 2.99 | IQ19: 5.99 | IS19: 9.2 | IT19: 2 | IU19: 3 | IV19: 4 | IY19: 1 Day | IZ19: test1 | JA19: Imported | JB19: GEN STANDARD
B20: 29069 | C20: Example Women T-shirt, 156 Black T-shirt | D20: EXAMPLE-156-US | E20: EXAMPLE-156-US-Black-M | H20: Unleash your personal style with our classic fit tee. Crafted from 100% cotton, it offers unmatched comfort and durability. The tee features a unique, eye-catching graphic that embodies modern chic. Perfect for casual outings or layering under a jacket, this T-shirt is versatile for any occasion. With a breathable fabric that holds its shape, it's a wardrobe staple you'll reach for time and again. Make a statement and stay cozy in a shirt designed to express who you are. (Character count: 493) | I20: 100% premium cotton for ultimate comfort. | J20: Timeless design meets modern style. | K20: Durable fabric, perfect for daily wear | L20: Machine washable and easy to care for. | M20: Versatile fit for every body type. | O20: http://www.companyname.com/images/1250.main.jpg | P20: http://www.companyname.com/images/1250.main.jpg | Q20: http://www.companyname.com/images/1250.main.jpg | R20: http://www.companyname.com/images/1250.main.jpg | CO20: Recycle Polyester | DS20: Y2K | ER20: 32 | ES20: 28 | ET20: 40 | FY20: Short Length | FZ20: Yes | GA20: Long Sleeve | GB20: Raglan sleeve | GC20: No Padding | GD20: Fake Pockets | GE20: Mushroom | GF20: No | GG20: Non-Stretch | GH20: Half Placket | GI20: Cashmere | GJ20: H | GK20: Fall | GL20: Do not wash | GM20: Regular | GN20: No Elasticity | GO20: Positioning Printing | GP20: Buyer provides | GQ20: Woven | GR20: Off the Shoulder | GS20: Middle East | GT20: Size × Color | GU20: US/EU size | GV20: Alpha | GW20: M | GX20: Black | HL20: cm | HM20: 2 | HO20: 40 | HP20: 29 | HW20: 35.5 | HX20: 37 | HY20: 27.6 | HZ20: 29.2 | IA20: 27.4 | IB20: 39 | IE20: http://www.companyname.com/images/1250.main.jpg | IF20: http://www.companyname.com/images/1250.main.jpg | IG20: http://www.companyname.com/images/1250.main.jpg | IO20: 5 | IP20: 2.99 | IQ20: 5.99 | IS20: 9.2 | IT20: 2 | IU20: 3 | IV20: 4 | IY20: 1 Day | IZ20: test1 | JA20: Imported | JB20: GEN STANDARD
B21: 29069 | C21: Example Women T-shirt, 156 Black T-shirt | D21: EXAMPLE-156-US | E21: EXAMPLE-156-US-red-S | H21: Unleash your personal style with our classic fit tee. Crafted from 100% cotton, it offers unmatched comfort and durability. The tee features a unique, eye-catching graphic that embodies modern chic. Perfect for casual outings or layering under a jacket, this T-shirt is versatile for any occasion. With a breathable fabric that holds its shape, it's a wardrobe staple you'll reach for time and again. Make a statement and stay cozy in a shirt designed to express who you are. (Character count: 493) | I21: 100% premium cotton for ultimate comfort. | J21: Timeless design meets modern style. | K21: Durable fabric, perfect for daily wear | L21: Machine washable and easy to care for. | M21: Versatile fit for every body type. | O21: http://www.companyname.com/images/1250.main.jpg | P21: http://www.companyname.com/images/1250.main.jpg | Q21: http://www.companyname.com/images/1250.main.jpg | R21: http://www.companyname.com/images/1250.main.jpg | CO21: Recycle Polyester | DS21: Y2K | ER21: 32 | ES21: 28 | ET21: 40 | FY21: Short Length | FZ21: Yes | GA21: Long Sleeve | GB21: Raglan sleeve | GC21: No Padding | GD21: Fake Pockets | GE21: Mushroom | GF21: No | GG21: Non-Stretch | GH21: Half Placket | GI21: Cashmere | GJ21: H | GK21: Fall | GL21: Do not wash | GM21: Regular | GN21: No Elasticity | GO21: Positioning Printing | GP21: Buyer provides | GQ21: Woven | GR21: Off the Shoulder | GS21: Middle East | GT21: Size × Color | GU21: US/EU size | GV21: Alpha | GW21: S | GX21: Red | HL21: cm | HM21: 0 | HO21: 36 | HP21: 28 | HW21: 33.9 | HX21: 35.5 | HY21: 26 | HZ21: 27.6 | IA21: 35.9 | IB21: 37.4 | IE21: http://www.companyname.com/images/1250.main.jpg | IF21: http://www.companyname.com/images/1250.main.jpg | IG21: http://www.companyname.com/images/1250.main.jpg | IO21: 5 | IP21: 3.99 | IQ21: 7.99 | IS21: 9.2 | IT21: 2 | IU21: 3 | IV21: 4 | IY21: 1 Day | IZ21: test1 | JA21: Imported | JB21: GEN STANDARD
B22: 29069 | C22: Example Women T-shirt, 156 Black T-shirt | D22: EXAMPLE-156-US | E22: EXAMPLE-156-US-red-M | H22: Unleash your personal style with our classic fit tee. Crafted from 100% cotton, it offers unmatched comfort and durability. The tee features a unique, eye-catching graphic that embodies modern chic. Perfect for casual outings or layering under a jacket, this T-shirt is versatile for any occasion. With a breathable fabric that holds its shape, it's a wardrobe staple you'll reach for time and again. Make a statement and stay cozy in a shirt designed to express who you are. (Character count: 493) | I22: 100% premium cotton for ultimate comfort. | J22: Timeless design meets modern style. | K22: Durable fabric, perfect for daily wear | L22: Machine washable and easy to care for. | M22: Versatile fit for every body type. | O22: http://www.companyname.com/images/1250.main.jpg | P22: http://www.companyname.com/images/1250.main.jpg | Q22: http://www.companyname.com/images/1250.main.jpg | R22: http://www.companyname.com/images/1250.main.jpg | CO22: Recycle Polyester | DS22: Y2K | ER22: 32 | ES22: 28 | ET22: 40 | FY22: Short Length | FZ22: Yes | GA22: Long Sleeve | GB22: Raglan sleeve | GC22: No Padding | GD22: Fake Pockets | GE22: Mushroom | GF22: No | GG22: Non-Stretch | GH22: Half Placket | GI22: Cashmere | GJ22: H | GK22: Fall | GL22: Do not wash | GM22: Regular | GN22: No Elasticity | GO22: Positioning Printing | GP22: Buyer provides | GQ22: Woven | GR22: Off the Shoulder | GS22: Middle East | GT22: Size × Color | GU22: US/EU size | GV22: Alpha | GW22: M | GX22: Red | HL22: cm | HM22: 2 | HO22: 40 | HP22: 29 | HW22: 35.5 | HX22: 37 | HY22: 27.6 | HZ22: 29.2 | IA22: 27.4 | IB22: 39 | IE22: http://www.companyname.com/images/1250.main.jpg | IF22: http://www.companyname.com/images/1250.main.jpg | IG22: http://www.companyname.com/images/1250.main.jpg | IO22: 5 | IP22: 3.99 | IQ22: 7.99 | IS22: 9.2 | IT22: 2 | IU22: 3 | IV22: 4 | IY22: 1 Day | IZ22: test1 | JA22: Imported | JB22: GEN STANDARD
B23: 12408 | C23: Example reclaimed Cabinet Solid Wood with 4 Drawers | D23: EXAMPLE-576 | E23: Example_Brand Night Stand with 4 Drawers (White, 21 inch) | DL23: Wood | DQ23: Painted | DR23: Cedar | DS23: Vintage | DT23: Plug Powered | DU23: 110V (included)-240V (included) | DV23: US Plug | DZ23: Yes | EA23: Hardwood | EC23: Block Board (large Core Board) | EG23: Yes | EH23: <3.2 Cubic Feet | EI23: <27 Inches | EJ23: <30 Lbs | EK23: Without Battery | EQ23: Red | GT23: Color × Size | GY23: White | GZ23: 21 inch | IE23: http://www.companyname.com/images/1250.main.jpg | IF23: http://www.companyname.com/images/1250.main.jpg | IG23: http://www.companyname.com/images/1250.main.jpg | IO23: 5 | IP23: 2.99 | IQ23: 5.99 | IS23: 9.2 | IT23: 2 | IU23: 3 | IV23: 4 | IY23: 1 Day | IZ23: test1 | JA23: Imported | JB23: GEN STANDARD
B24: 12408 | C24: Example reclaimed Cabinet Solid Wood with 4 Drawers | D24: EXAMPLE-576 | E24: Example_Brand Night Stand with 2 Drawers (White, 24 inch) | DL24: Wood | DQ24: Painted | DR24: Cedar | DS24: Vintage | DT24: Plug Powered | DU24: 110V (included)-240V (included) | DV24: US Plug | DZ24: Yes | EA24: Hardwood | EC24: Block Board (large Core Board) | EG24: Yes | EH24: <3.2 Cubic Feet | EI24: <27 Inches | EJ24: <30 Lbs | EK24: Without Battery | EQ24: Red | GT24: Color × Size | GY24: White | GZ24: 24 inch | IE24: http://www.companyname.com/images/1250.main.jpg | IF24: http://www.companyname.com/images/1250.main.jpg | IG24: http://www.companyname.com/images/1250.main.jpg | IO24: 5 | IP24: 2.99 | IQ24: 5.99 | IS24: 9.2 | IT24: 2 | IU24: 3 | IV24: 4 | IY24: 1 Day | IZ24: test1 | JA24: Imported | JB24: GEN STANDARD
B25: 12408 | C25: Example reclaimed Cabinet Solid Wood with 4 Drawers | D25: EXAMPLE-576 | E25: Example_Brand Night Stand with 2 Drawers (Grey, 21 inch) | DL25: Wood | DQ25: Painted | DR25: Cedar | DS25: Vintage | DT25: Plug Powered | DU25: 110V (included)-240V (included) | DV25: US Plug | DZ25: Yes | EA25: Hardwood | EC25: Block Board (large Core Board) | EG25: Yes | EH25: <3.2 Cubic Feet | EI25: <27 Inches | EJ25: <30 Lbs | EK25: Without Battery | EQ25: Red | GT25: Color × Size | GY25: Grey | GZ25: 21 inch | IE25: http://www.companyname.com/images/1250.main.jpg | IF25: http://www.companyname.com/images/1250.main.jpg | IG25: http://www.companyname.com/images/1250.main.jpg | IO25: 5 | IP25: 2.99 | IQ25: 5.99 | IS25: 9.2 | IT25: 2 | IU25: 3 | IV25: 4 | IY25: 1 Day | IZ25: test1 | JA25: Imported | JB25: GEN STANDARD
B26: 12408 | C26: Example reclaimed Cabinet Solid Wood with 4 Drawers | D26: EXAMPLE-576 | E26: Example_Brand Night Stand with 2 Drawers (Grey, 24 inch) | DL26: Wood | DQ26: Painted | DR26: Cedar | DS26: Vintage | DT26: Plug Powered | DU26: 110V (included)-240V (included) | DV26: US Plug | DZ26: Yes | EA26: Hardwood | EC26: Block Board (large Core Board) | EG26: Yes | EH26: <3.2 Cubic Feet | EI26: <27 Inches | EJ26: <30 Lbs | EK26: Without Battery | EQ26: Red | GT26: Color × Size | GY26: Grey | GZ26: 24 inch | IE26: http://www.companyname.com/images/1250.main.jpg | IF26: http://www.companyname.com/images/1250.main.jpg | IG26: http://www.companyname.com/images/1250.main.jpg | IO26: 5 | IP26: 2.99 | IQ26: 5.99 | IS26: 9.2 | IT26: 2 | IU26: 3 | IV26: 4 | IY26: 1 Day | IZ26: test1 | JA26: Imported | JB26: GEN STANDARD

Sheet Datendefinitionen
A1: So füllen Sie Ihre Vorlage aus
A2: Gruppenname | B2: Namensfeld | C2: Lokale Bezeichnung des Etiketts | D2: Definition und Verwendung | E2: Akzeptierte Werte | F2: Beispiel | G2: Erforderlich oder nicht erforderlich
A3: Produktidentität: Dies sind Attribute, die für Käufer wichtig sind und für alle Ihre Artikel ausgefüllt werden müssen. Einige sind erforderlich, um ein Angebot zu erstellen.
B4: t_1_category | C4: Kategorie | D4: Unterstützt nur das Hochladen einer einzelnen Warenkategorie. Kategorie-ID wurde in der Dropdown-Liste voreingestellt. | E4: Geben Sie eine geeignete Kategorie ein. | F4: 13788 | G4: Erforderlich
B5: t_1_productname | C5: Produktname | D5: Gemäß den Richtlinien des Verkäufercenters: Maximal 500 Zeichen, darf keine leeren Zeilen oder mehr als zwei aufeinander folgende Leerzeichen enthalten. | E5: Der Produktname darf nicht länger als 500 Zeichen sein, einschließlich Leerzeichen. Zulässige Zeichen sind Buchstaben, Zahlen und Symbole. Emojis oder andere Sonderzeichen können nicht verwendet werden. Es wird empfohlen, maximal 80 Zeichen zu verwenden, da lange Produktnamen auf Mobilgeräten abgeschnitten werden können. | F5: Robert Graham Herrenhemd „Maya Bay“, Kurzarm, Classic Fit, Cranberry, Größe XL | G5: Erforderlich
B6: t_1_contributiongoods | C6: Verkäufer Goods | D6: Der Code, der Anbietern zur Kennzeichnung und Verwaltung von übergeordneten Produktlinks bereitgestellt wird; wird vom Händler eingegeben. Muss innerhalb des Stores eindeutig sein. Zeilen mit demselben Beitragswarenwert werden vom System als unterschiedliche untergeordnete SKUs desselben übergeordneten Produkts behandelt. Verwenden Sie in SKUs keine voran- oder nachgestellten Leerzeichen. | E6: Dieses Attribut gibt die Produktnummer an, die vom Beitragenden zugewiesen wurde | F6: ABC123 | G6: Erforderlich
B7: t_1_contributionsku | C7: Verkäufer SKU | D7: Der Code, der Anbietern zur Kennzeichnung und Verwaltung von Unterproduktlinks bereitgestellt wird; wird vom Händler eingegeben. Muss innerhalb des Stores eindeutig sein. Verwenden Sie in SKUs keine voran- oder nachgestellten Leerzeichen. | E7: Dieses Attribut gibt die SKU-Nummer an, die vom Beitragenden zugewiesen wurde | F7: ABC123 | G7: Erforderlich
B8: t_1_Update or Add | C8: Aktualisieren oder hinzufügen | D8: Geben Sie die Art des Vorgangs an („Update“: Update; „Partial Update“: partielles Update) an, der mit den angegebenen Daten durchgeführt werden soll. Wenn Sie das Feld leer lassen, lautet die Standardoption „Update“. Verwenden Sie „Update“, wenn Sie vorhandene Produktinformationen bearbeiten oder ein neues Produkt erstellen, und geben Sie „Partial Update“ ein, wenn nur die eingegebenen Produktinformationsfelder aktualisiert werden. | E8: Wählen Sie eine der folgenden Optionen aus: Update, PartialUpdate. | F8: Aktualisieren | G8: Optional
B9: t_1_Goods Id | C9: Warennummer | D9: Geben Sie nur bei der Bearbeitung bestehender Produktinformationen die von Temu generierte Waren-ID ein. | G9: Optional
B10: t_1_Sku Id | C10: SKU-ID | D10: Geben Sie nur bei der Bearbeitung bestehender Produktinformationen die von Temu generierte SKU-ID ein. | G10: Optional
B11: t_1_brand | C11: Marke | D11: Wenn für das Produkt Markeninformationen erforderlich sind, wählen Sie bitte sowohl die Marke als auch das Markenzeichen des Produkts aus. | E11: Wählen Sie den Markennamen des Produkts aus https://seller-eu.temu.com/performance/account-health.html?tab=compliance&opType=register | F11: Nike | G11: Optional
B12: t_1_trademark | C12: Markenzeichen | D12: Wenn für das Produkt Markeninformationen erforderlich sind, wählen Sie bitte sowohl die Marke als auch das Markenzeichen des Produkts aus. Bitte gehen Sie bei der Auswahl der Marke und des Markenzeichens, die du zuordnen möchtest, umsichtig vor. | E12: Wählen Sie den Markenzeichennamen des Produkts aus | F12: Nike | G12: Optional
A13: Produktbeschreibung: Diese Attribute wirken sich darauf aus, wie Kunden Ihr Produkt auf der Website durch Blättern oder Suchen finden können
B14: t_2_productdescription | C14: Produktbeschreibung | D14: Eine Textbeschreibung des Produkts. | E14: Entsprechend den MMS-Leitlinien: Maximal 2000 Zeichen, die Rich Text-Formatierung wird nicht unterstützt. | F14: Langärmlige Strickjacke mit V-Ausschnitt, gerippter Taille und Taschen mit Schleifendetails | G14: Optional
B15: t_2_bulletpoint | C15: Aufzählungspunkt | D15: Kurzer beschreibender Text in Form von Aufzählungspunkten zu jeweils einem bestimmten Aspekt des Produkts. Diese werden direkt unter oder neben Ihrem Produktfoto angezeigt. Es ist sinnvoll, in diese Felder interessante Informationen einzugeben. Aufzählungspunkte werden automatisch eingefügt. | E15: Entsprechend den MMS-Leitlinien: Maximal 700 Zeichen, die Rich Text-Formatierung wird nicht unterstützt. Sie können pro Zelle einen Aufzählungspunkt hochladen | F15: Hergestellt mit pflegendem, reinem Aloe-Vera-Gel | G15: Optional
B16: t_2_detailimagesurl | C16: URL für Detailbilder | D16: Rufen Sie die URLs von einer beliebigen Bildhosting-Website ab und geben Sie sie in die entsprechenden Zellen ein. i. Seitenverhältnis: 1:1, 4:3, 16:9 ii. Auflösung: min. 720 p iii. Dauer: max. 180 Sek. iv. Dateigröße: max. 300 MB v. Dateitypen: WMV, AVI, 3GP, MOV, MP4, FLV, RMVB, MKV, M4V, X-FLV | E16: Rufen Sie die URLs von einer beliebigen Bildhosting-Website ab und geben Sie sie in die entsprechenden Zellen ein. i. Seitenverhältnis: min. 1:3; ii. Breite oder Höhe: min. 480 px; iii. Dateigröße: max. 3 MB; iv. Dateitypen: JPEG, JPG, PNG | F16: http://www.companyname.com/images/1250.main.jpg | G16: Optional
B17: t_2_detailvideourl | C17: Detail-Video-URL | D17: Die URL für das Detailvideo zu deinem Produkt. Das Detailvideo wird oben im Abschnitt mit den Produktdetails angezeigt. | E17: Rufen Sie die URLs von einer beliebigen Bildhosting-Website ab und geben Sie sie in die entsprechenden Zellen ein. i. Seitenverhältnis: 1:1, 4:3, 16:9 ii. Auflösung: min. 720 p iii. Dauer: max. 180 Sek. iv. Dateigröße: max. 300 MB v. Dateitypen: WMV, AVI, 3GP, MOV, MP4, FLV, RMVB, MKV, M4V, X-FLV | F17: http://www.companyname.com/videos/1250..mp4 | G17: Optional
A18: Verkaufseigenschaft (mindestens eine, höchstens zwei): Diese Attribute für das Produkt werden für verschiedene Variationen bereitgestellt
B19: t_4_variationtheme | C19: Variationsdesign | D19: Beschreibt die Parameter, um die das übergeordnete Produkt variieren kann. Der eingegebene Wert für dieses Feld muss für alle SKUs desselben Produkts identisch sein. Beispiel: Wenn das Produkt je nach Größe variiert, geben Sie den Wert „Größe“ ein. Wenn das Produkt je nach Farbe variiert, geben Sie den Wert „Farbe“ ein. Begriffe, die für Variationsdesigns verwendet werden, werden von Ihnen, also vom Händler erstellt. (Beispiel: „Menge“ kann eine beliebige Zahl sein) | E19: Wählen Sie ein zutreffendes Variationsdesign aus. | F19: Color × Size | G19: Erforderlich
A20: Variationen: Diese Attribute sind für die Käufer wichtig und sollten für die SKU des Produkts eingetragen werden
B21: t_5_skuimagesurl | C21: URL für SKU-Bilder | D21: SKU-Bilder werden oben auf der Produktseite angezeigt, wenn der Kunde durchklickt, um andere mit dem Produkt verknüpfte Ansichten anzuzeigen. Verschiedene SKU-Bilder bilden ein Produktkarussell. Sie können dieses Feld beispielsweise verwenden, um die Informationen auf dem Etikett oder die Verpackung Ihres Produkts anzuzeigen. Laden Sie zusätzliche Bilder hoch, die verschiedene Ansichten des Artikels zeigen oder den Artikel in einer emotional ansprechenden Umgebung darstellen. | E21: a. Für Kleidung: i. Seitenverhältnis: 3:4 ii. Breite: min. 1340 px iii. Höhe: min. 1785 px iv. Dateigröße: max. 3 MB v. Dateitypen: JPEG, JPG, PNG b. Für andere Produkte: i. Seitenverhältnis: 1:1 ii. Breite oder Höhe: min. 800 px iii. Dateigröße: max. 3 MB iv. Dateitypen: JPEG, JPG, PNG | F21: http://www.companyname.com/images/1250.main.jpg | G21: Erforderlich
B22: t_5_dimensions | C22: Abmessungen | D22: Bitte verwenden Sie zur Angabe der Produktabmessungen imperiale Einheiten. Dies kann Käufern helfen, die Größe und die Spezifikationen des Produkts besser einzuschätzen. | E22: a. Für Kleidung: i. Seitenverhältnis: 3:4 ii. Breite: min. 1340 px iii. Höhe: min. 1785 px iv. Dateigröße: max. 3 MB v. Dateitypen: JPEG, JPG, PNG b. Für andere Produkte: i. Seitenverhältnis: 1:1 ii. Breite oder Höhe: min. 800 px iii. Dateigröße: max. 3 MB iv. Dateitypen: JPEG, JPG, PNG | F22: http://www.companyname.com/images/1250.dimension.jpg | G22: Optional
B23: t_5_condition | C23: Zustand | D23: Das Feld „Zustand“ wird verwendet, um den Zustand eines gebrauchten Produkts zu beschreiben, einschließlich verschiedener Qualitätsstufen. Der Zustand muss für die Verbraucher angezeigt werden, um bei der Kaufentscheidung zu helfen. Alle SKUs in einem Produkt müssen die Einstellung für „Zustände“ aufweisen. | E23: Wählen Sie eine geeignete Option für das Produkt aus. Verschiedene Kategorien haben unterschiedliche Standards zur Einstufung der Zustandsstufen. Sie können sie im Temu Seller Center einsehen. | F23: Used - Like new | G23: Erforderlich
B24: t_5_quantity | C24: Anzahl | D24: Geben Sie die Menge des Artikels ein, die Sie zum Verkauf anbieten. Dies ist Ihre aktuelle BESTANDSVERPFLICHTUNG. Die Angabe der Menge ist für alle „untergeordneten“ oder eigenständigen Artikel erforderlich. Wenn Sie das Feld bei der ersten Übermittlung der Produktinformationen leer lassen, wird der Artikel als „Nicht vorrätig“ angezeigt. | E24: Geben Sie die Menge des Artikels ein, die Sie zum Verkauf anbieten. Dies ist Ihre aktuelle Bestandsverpflichtung (als ganze Zahl) | F24: 152 | G24: Erforderlich
B25: t_5_base_price_eur | C25: Grundpreis | D25: Der Basispreis sollte Ihre Kosten und den erwarteten Gewinn widerspiegeln. Sie erhalten Verkaufserlöse auf der Grundlage des operativen Preises für jedes verkaufte Produkt. Der endgültige Einzelhandelspreis ist nicht direkt mit Ihrer Zahlungsabrechnung verknüpft. Der Basispreis muss niedriger als der Listenpreis sein. | E25: Der Preisbereich liegt zwischen 0,01 € und 99999999,99 € mit maximal 2 Dezimalstellen und wird aufgerundet. | F25: 3.99 | G25: Erforderlich
B26: t_5_Reference Link | C26: Referenzlink | D26: Geben Sie (einen) Link(s) zu diesem Produkt aus anderen Quellen als Referenz an, um die Preisanpassung zu beschleunigen. | E26: Links zu diesem Produkt auf anderen Plattformen beginnen mit „https://“ oder „http://“
B27: t_5_list_price_eur | C27: Unverbindliche Preisempfehlung | D27: <div>Die unverbindliche Preisempfehlung (UVP) ist der vorgeschlagene oder empfohlene Einzelhandelspreis eines Produkts, der vom Hersteller festgelegt wird. </div><div style='margin-top: 4px'><span style='color: #FB7701'>Die UVP muss ein echter Verkaufspreis auf dem Zielmarkt sein</span> und den geltenden Gesetzen und Vorschriften entsprechen. Das bedeutet, dass dasselbe Produkt in letzter Zeit von anderen Einzelhändlern in diesem Markt tatsächlich zu der UVP beworben und verkauft worden sein muss. Wenn Ihr Produkt nicht über eine UVP verfügt, die alle diese Kriterien erfüllt, können Sie diese UVP nicht eingeben, müssen aber N/A („Not available“ = „Nicht verfügbar“) eingeben. Sie müssen sicherstellen, dass alle genannten UVP aktualisiert werden, falls zutreffend.</div><div style='margin-top: 4px; color: #FB7701'><div>Durch die Eingabe einer UVP bestätigen Sie Folgendes:</div><div>• Sie sind nicht der einzige Verkäufer des Produkts auf dem Markt, auf dem das Produkt verkauft wird (und wo ein UVP-Vergleich durchgeführt wird);</div><div>• Die UVP, die Sie angeben, ist aktuell;</div><div>• Sie haben Nachweise dafür, dass es sich bei der UVP, die Sie angeben, um einen echten Preis handelt, zu dem das Produkt in letzter Zeit von anderen Einzelhändlern auf dem Zielmarkt beworben und verkauft wurde, und dass die UVP vom Hersteller sorgfältig berechnet und ausgewiesen wurde. Sie müssen Temu diese Nachweise auf Anfrage zur Verfügung stellen.</div></div><div style='margin-top: 4px'>Temu kann jede Angabe einer UVP nach eigenem Ermessen entfernen, wenn Temu darüber Kenntnis hat oder Temu bewusst wird, dass die oben genannten Kriterien für eine konforme UVP nicht erfüllt werden.</div> | E27: Der Preisbereich liegt zwischen 0,01 € und 99999999,99 € mit maximal 2 Dezimalstellen und wird aufgerundet. | F27: 5.79 | G27: Optional
B28: t_5_notavailableforlistprice | C28: Nicht verfügbar für Listenpreis | D28: list_price_4_RRP | E28: Wählen Sie „Nicht zutreffend (N/A)“, wenn Ihr Produkt keine unverbindliche Preisempfehlung hat | F28: N/A | G28: Erforderlich
B29: t_5_weight_lb | C29: Gewicht des Pakets | D29: Diese Angabe zeigt das Paketgewicht der SKU an und wird von Temu zur Einschätzung der Logistikkosten verwendet. Bitte geben Sie dies korrekt ein. | E29: Der Gewichtsbereich liegt zwischen 0,1 g und 9999999,9 g mit maximal 1 Dezimalstelle und wird aufgerundet | F29: 10.2 | G29: Optional
B30: t_5_length_in | C30: Länge | D30: Diese Angabe zeigt das Paketvolumen der SKU an und wird von Temu zur Einschätzung der Logistikkosten verwendet. Bitte geben Sie dies korrekt ein. | E30: Der Längenbereich liegt zwischen 0,1 cm und 9999,9 cm mit maximal 1 Dezimalstelle und wird aufgerundet | F30: 3.1 | G30: Optional
B31: t_5_width_in | C31: Breite | D31: Diese Angabe zeigt das Paketvolumen der SKU an und wird von Temu zur Einschätzung der Logistikkosten verwendet. Bitte geben Sie dies korrekt ein. | E31: Der Längenbereich liegt zwischen 0,1 cm und 9999,9 cm mit maximal 1 Dezimalstelle und wird aufgerundet | F31: 2.1 | G31: Optional
B32: t_5_height_in | C32: Höhe | D32: Diese Angabe zeigt das Paketvolumen der SKU an und wird von Temu zur Einschätzung der Logistikkosten verwendet. Bitte geben Sie dies korrekt ein. | E32: Der Längenbereich liegt zwischen 0,1 cm und 9999,9 cm mit maximal 1 Dezimalstelle und wird aufgerundet | F32: 1.1 | G32: Optional
B33: t_5_externalproductidtype | C33: Externer Produkt-ID-Typ | D33: Der Typ der standardmäßigen, eindeutigen Kennung, die in das Produkt-ID-Feld eingegeben wird. Dies ist ein Pflichtfeld, wenn die Produkt-ID angegeben wird. | E33: Der Typ der standardmäßigen, eindeutigen Kennung, die in das Produkt-ID-Feld eingegeben wird. Dies ist ein Pflichtfeld, wenn die Produkt-ID angegeben wird. | F33: UPC | G33: Erforderlich
B34: t_5_externalproductid | C34: Externe Produktnummer | D34: Eine alphanumerische Standardzeichenfolge, die das Produkt eindeutig identifiziert. Dies kann eine GCID- (16 alphanumerische Zeichen), UPC- oder EAN-Nummer sein. Dies ist ein Pflichtfeld, wenn product_id_type angegeben ist. | E34: Geben Sie den entsprechenden Wert für die externe Produkt-ID basierend auf dem ausgewählten Typ an | F34: 714532191586 | G34: Erforderlich
A35: Angebot: Diese Attribute sind erforderlich, um Ihr Produkt für Kunden auf der Website verfügbar zu machen
